<?xml version="1.0"?>
<robot name="go2" xmlns:xacro="http://ros.org/wiki/xacro">

  <!-- Base Link -->
  <link name="base_link">
    <inertial>
      <origin xyz="0.021112 0 -0.005366" rpy="0 0 0"/>
      <mass value="6.921"/>
      <inertia ixx="0.02448" ixy="0.00012166" ixz="0.0014849" iyy="0.098077" iyz="-3.12E-05" izz="0.107"/>
    </inertial>
    <visual>
      <origin xyz="0 0 0" rpy="0 0 0"/>
      <geometry>
        <mesh filename="package://dae/base.dae"/>
      </geometry>
      <material name="">
        <color rgba="1 1 1 1"/>
      </material>
    </visual>
    <collision>
      <origin rpy="0 0 0" xyz="0 0 0"/>
      <geometry>
        <mesh filename="package://dae/base.dae"/>
      </geometry>
    </collision>
  </link>

  <!-- ========== FRONT LEFT LEG ========== -->
  <link name="FL_hip">
    <inertial>
      <origin xyz="-0.0054 0.00194 -0.000105" rpy="0 0 0"/>
      <mass value="0.678"/>
      <inertia ixx="0.00048" ixy="-3.01E-06" ixz="1.11E-06" iyy="0.000884" iyz="-1.42E-06" izz="0.000596"/>
    </inertial>
    <visual>
      <origin xyz="0 0 0" rpy="0 0 0"/>
      <geometry>
        <mesh filename="package://dae/hip.dae"/>
      </geometry>
      <material name="">
        <color rgba="1 1 1 1"/>
      </material>
    </visual>
    <collision>
      <origin rpy="1.5707963267948966 0 0" xyz="0 0.08 0"/>
      <geometry>
        <cylinder length="0.04" radius="0.046"/>
      </geometry>
    </collision>
  </link>

  <joint name="FL_hip_joint" type="revolute">
    <origin xyz="0.1934 0.0465 0" rpy="0 0 0"/>
    <parent link="base_link"/>
    <child link="FL_hip"/>
    <axis xyz="1 0 0"/>
    <limit lower="-1.0472" upper="1.0472" effort="23.7" velocity="30.1"/>
  </joint>

  <link name="FL_thigh">
    <inertial>
      <origin xyz="-0.00374 -0.0223 -0.0327" rpy="0 0 0"/>
      <mass value="1.152"/>
      <inertia ixx="0.00584" ixy="8.72E-05" ixz="-0.000289" iyy="0.0058" iyz="0.000808" izz="0.00103"/>
    </inertial>
    <visual>
      <origin xyz="0 0 0" rpy="0 0 0"/>
      <geometry>
        <mesh filename="package://dae/thigh.dae"/>
      </geometry>
      <material name="">
        <color rgba="1 1 1 1"/>
      </material>
    </visual>
    <collision>
      <geometry>
        <mesh filename="package://dae/thigh.dae"/>
      </geometry>
    </collision>
  </link>

  <joint name="FL_thigh_joint" type="revolute">
    <origin xyz="0 0.0955 0" rpy="0 0 0"/>
    <parent link="FL_hip"/>
    <child link="FL_thigh"/>
    <axis xyz="0 1 0"/>
    <limit lower="-1.5708" upper="3.4907" effort="23.7" velocity="30.1"/>
  </joint>

  <link name="FL_calf">
    <inertial>
      <origin xyz="0.00548 -0.000975 -0.115" rpy="0 0 0"/>
      <mass value="0.154"/>
      <inertia ixx="0.00108" ixy="3.4E-07" ixz="1.72E-05" iyy="0.0011" iyz="8.28E-06" izz="3.29E-05"/>
    </inertial>
    <visual>
      <origin xyz="0 0 0" rpy="0 0 0"/>
      <geometry>
       <mesh filename="package://dae/calf.dae"/>
      </geometry>
      <material name="">
        <color rgba="1 1 1 1"/>
      </material>
    </visual>
    <collision>
      <geometry>
        <mesh filename="package://dae/calf.dae"/>
      </geometry>
    </collision>
  </link>

  <joint name="FL_calf_joint" type="revolute">
    <origin xyz="0 0 -0.213" rpy="0 0 0"/>
    <parent link="FL_thigh"/>
    <child link="FL_calf"/>
    <axis xyz="0 1 0"/>
    <limit lower="-2.7227" upper="-0.83776" effort="45.43" velocity="15.70"/>
  </joint>

  <link name="FL_foot">
    <inertial>
      <origin xyz="0 0 0" rpy="0 0 0"/>
      <mass value="0.04"/>
      <inertia ixx="9.6e-06" ixy="0" ixz="0" iyy="9.6e-06" iyz="0" izz="9.6e-06"/>
    </inertial>
    <visual>
      <origin xyz="0 0 0" rpy="0 0 0"/>
      <geometry>
         <mesh filename="package://dae/foot.dae"/>
      </geometry>
      <material name="black">
        <color rgba="0 0 0 1"/>
      </material>
    </visual>
    <collision>
      <origin rpy="0 0 0" xyz="-0.002 0 0"/>
      <geometry>
        <sphere radius="0.022"/>
      </geometry>
    </collision>
  </link>

  <joint name="FL_foot_joint" type="fixed" dont_collapse="true">
    <origin xyz="0 0 -0.213" rpy="0 0 0"/>
    <parent link="FL_calf"/>
    <child link="FL_foot"/>
    <axis xyz="0 0 0"/>
  </joint>

  <link name="FL_shoulder">
    <inertial>
      <origin xyz="0 0 0" rpy="0 0 0"/>
      <mass value="0"/>
      <inertia ixx="0" ixy="0" ixz="0" iyy="0" iyz="0" izz="0"/>
    </inertial>
    <visual>
      <origin rpy="1.5708 0 0" xyz="0 0 0"/>
      <geometry>
        <sphere radius="0.005"/>
      </geometry>
        <material name="red">
      <color rgba="1 0 0 1"/>
    </material>
    </visual>
  </link>

    <joint name="FL_shoulder_joint" type="fixed">
      <origin xyz="-0.045 0 0" rpy="0 0 0"/>
      <parent link="FL_thigh"/>
      <child link="FL_shoulder"/>
      <axis xyz="0 1 0"/>
    </joint>

  <!-- ========== FRONT RIGHT LEG ========== -->
  <link name="FR_hip">
    <inertial>
      <origin xyz="-0.0054 -0.00194 -0.000105" rpy="0 0 0"/>
      <mass value="0.678"/>
      <inertia ixx="0.00048" ixy="3.01E-06" ixz="1.11E-06" iyy="0.000884" iyz="1.42E-06" izz="0.000596"/>
    </inertial>
    <visual>
      <origin xyz="0 0 0" rpy="3.1415 0 0"/>
      <geometry>
        <mesh filename="package://dae/hip.dae"/>
      </geometry>
      <material name="">
        <color rgba="1 1 1 1"/>
      </material>
    </visual>
    <collision>
      <origin rpy="1.5707963267948966 0 0" xyz="0 -0.08 0"/>
      <geometry>
        <cylinder length="0.04" radius="0.046"/>
      </geometry>
    </collision>
  </link>

  <joint name="FR_hip_joint" type="revolute">
    <origin xyz="0.1934 -0.0465 0" rpy="0 0 0"/>
    <parent link="base_link"/>
    <child link="FR_hip"/>
    <axis xyz="1 0 0"/>
    <limit lower="-1.0472" upper="1.0472" effort="23.7" velocity="30.1"/>
  </joint>

  <link name="FR_thigh">
    <inertial>
      <origin xyz="-0.00374 0.0223 -0.0327" rpy="0 0 0"/>
      <mass value="1.152"/>
      <inertia ixx="0.00584" ixy="-8.72E-05" ixz="-0.000289" iyy="0.0058" iyz="-0.000808" izz="0.00103"/>
    </inertial>
    <visual>
      <origin xyz="0 0 0" rpy="0 0 0"/>
      <geometry>
        <mesh filename="package://dae/thigh_mirror.dae"/>
      </geometry>
      <material name="">
        <color rgba="1 1 1 1"/>
      </material>
    </visual>
    <collision>
      <geometry>
        <mesh filename="package://dae/thigh_mirror.dae"/>
      </geometry>
    </collision>
  </link>

  <joint name="FR_thigh_joint" type="revolute">
    <origin xyz="0 -0.0955 0" rpy="0 0 0"/>
    <parent link="FR_hip"/>
    <child link="FR_thigh"/>
    <axis xyz="0 1 0"/>
    <limit lower="-1.5708" upper="3.4907" effort="23.7" velocity="30.1"/>
  </joint>

  <link name="FR_calf">
    <inertial>
      <origin xyz="0.00548 0.000975 -0.115" rpy="0 0 0"/>
      <mass value="0.154"/>
      <inertia ixx="0.00108" ixy="-3.4E-07" ixz="1.72E-05" iyy="0.0011" iyz="-8.28E-06" izz="3.29E-05"/>
    </inertial>
    <visual>
      <origin xyz="0 0 0" rpy="0 0 0"/>
      <geometry>
        <mesh filename="package://dae/calf_mirror.dae"/>
      </geometry>
      <material name="">
        <color rgba="1 1 1 1"/>
      </material>
    </visual>
    <collision>
      <geometry>
       <mesh filename="package://dae/calf_mirror.dae"/>
      </geometry>
    </collision>
  </link>

  <joint name="FR_calf_joint" type="revolute">
    <origin xyz="0 0 -0.213" rpy="0 0 0"/>
    <parent link="FR_thigh"/>
    <child link="FR_calf"/>
    <axis xyz="0 1 0"/>
    <limit lower="-2.7227" upper="-0.83776" effort="45.43" velocity="15.70"/>
  </joint>

  <link name="FR_foot">
    <inertial>
      <origin xyz="0 0 0" rpy="0 0 0"/>
      <mass value="0.04"/>
      <inertia ixx="9.6e-06" ixy="0" ixz="0" iyy="9.6e-06" iyz="0" izz="9.6e-06"/>
    </inertial>
    <visual>
      <origin xyz="0 0 0" rpy="0 0 0"/>
      <geometry>
        <mesh filename="package://dae/foot.dae"/>
      </geometry>
      <material name="black">
        <color rgba="0 0 0 1"/>
      </material>
    </visual>
    <collision>
      <origin rpy="0 0 0" xyz="-0.002 0 0"/>
      <geometry>
        <sphere radius="0.022"/>
      </geometry>
    </collision>
  </link>

  <joint name="FR_foot_joint" type="fixed" dont_collapse="true">
    <origin xyz="0 0 -0.213" rpy="0 0 0"/>
    <parent link="FR_calf"/>
    <child link="FR_foot"/>
    <axis xyz="0 0 0"/>
  </joint>

  <link name="FR_shoulder">
    <inertial>
      <origin xyz="0 0 0" rpy="0 0 0"/>
      <mass value="0"/>
      <inertia ixx="0" ixy="0" ixz="0" iyy="0" iyz="0" izz="0"/>
    </inertial>
    <visual>
      <origin rpy="1.5708 0 0" xyz="0 0 0"/>
      <geometry>
        <sphere radius="0.005"/>
      </geometry>
        <material name="red">
      <color rgba="1 0 0 1"/>
    </material>
    </visual>
  </link>

  <joint name="FR_shoulder_joint" type="fixed">
    <origin xyz="-0.045 0 0" rpy="0 0 0"/>
    <parent link="FR_thigh"/>
    <child link="FR_shoulder"/>
    <axis xyz="0 1 0"/>
  </joint>

  <!-- ========== REAR LEFT LEG ========== -->
  <link name="RL_hip">
    <inertial>
      <origin xyz="0.0054 0.00194 -0.000105" rpy="0 0 0"/>
      <mass value="0.678"/>
      <inertia ixx="0.00048" ixy="3.01E-06" ixz="-1.11E-06" iyy="0.000884" iyz="-1.42E-06" izz="0.000596"/>
    </inertial>
    <visual>
      <origin xyz="0 0 0" rpy="0 3.1415 0"/>
      <geometry>
        <mesh filename="package://dae/hip.dae"/>
      </geometry>
      <material name="">
        <color rgba="1 1 1 1"/>
      </material>
    </visual>
    <collision>
      <origin xyz="0 0 0" rpy="0 3.1415 0"/>
      <geometry>
        <mesh filename="package://dae/hip.dae"/>
      </geometry>
    </collision>
  </link>

  <joint name="RL_hip_joint" type="revolute">
    <origin xyz="-0.1934 0.0465 0" rpy="0 0 0"/>
    <parent link="base_link"/>
    <child link="RL_hip"/>
    <axis xyz="1 0 0"/>
    <limit lower="-1.0472" upper="1.0472" effort="23.7" velocity="30.1"/>
  </joint>

  <link name="RL_thigh">
    <inertial>
      <origin xyz="-0.00374 -0.0223 -0.0327" rpy="0 0 0"/>
      <mass value="1.152"/>
      <inertia ixx="0.00584" ixy="8.72E-05" ixz="-0.000289" iyy="0.0058" iyz="0.000808" izz="0.00103"/>
    </inertial>
    <visual>
      <origin xyz="0 0 0" rpy="0 0 0"/>
      <geometry>
        <mesh filename="package://dae/thigh.dae"/>
      </geometry>
      <material name="">
        <color rgba="1 1 1 1"/>
      </material>
    </visual>
    <collision>
      <geometry>
        <mesh filename="package://dae/thigh.dae"/>
      </geometry>
    </collision>
  </link>

  <joint name="RL_thigh_joint" type="revolute">
    <origin xyz="0 0.0955 0" rpy="0 0 0"/>
    <parent link="RL_hip"/>
    <child link="RL_thigh"/>
    <axis xyz="0 1 0"/>
    <limit lower="-0.5236" upper="4.5379" effort="23.7" velocity="30.1"/>
  </joint>

  <link name="RL_calf">
    <inertial>
      <origin xyz="0.00548 -0.000975 -0.115" rpy="0 0 0"/>
      <mass value="0.154"/>
      <inertia ixx="0.00108" ixy="3.4E-07" ixz="1.72E-05" iyy="0.0011" iyz="8.28E-06" izz="3.29E-05"/>
    </inertial>
    <visual>
      <origin xyz="0 0 0" rpy="0 0 0"/>
      <geometry>
         <mesh filename="package://dae/calf.dae"/>
      </geometry>
      <material name="">
        <color rgba="1 1 1 1"/>
      </material>
    </visual>
    <collision>
      <geometry>
         <mesh filename="package://dae/calf.dae"/>
      </geometry>
    </collision>
  </link>

  <joint name="RL_calf_joint" type="revolute">
    <origin xyz="0 0 -0.213" rpy="0 0 0"/>
    <parent link="RL_thigh"/>
    <child link="RL_calf"/>
    <axis xyz="0 1 0"/>
    <limit lower="-2.7227" upper="-0.83776" effort="45.43" velocity="15.70"/>
  </joint>

  <link name="RL_foot">
    <inertial>
      <origin xyz="0 0 0" rpy="0 0 0"/>
      <mass value="0.04"/>
      <inertia ixx="9.6e-06" ixy="0" ixz="0" iyy="9.6e-06" iyz="0" izz="9.6e-06"/>
    </inertial>
    <visual>
      <origin xyz="0 0 0" rpy="0 0 0"/>
      <geometry>
        <mesh filename="package://dae/foot.dae"/>
      </geometry>
      <material name="black">
        <color rgba="0 0 0 1"/>
      </material>
    </visual>
    <collision>
      <origin rpy="0 0 0" xyz="-0.002 0 0"/>
      <geometry>
        <sphere radius="0.022"/>
      </geometry>
    </collision>
  </link>

  <joint name="RL_foot_joint" type="fixed" dont_collapse="true">
    <origin xyz="0 0 -0.213" rpy="0 0 0"/>
    <parent link="RL_calf"/>
    <child link="RL_foot"/>
    <axis xyz="0 0 0"/>
  </joint>

    <link name="RL_shoulder">
    <inertial>
      <origin xyz="0 0 0" rpy="0 0 0"/>
      <mass value="0"/>
      <inertia ixx="0" ixy="0" ixz="0" iyy="0" iyz="0" izz="0"/>
    </inertial>
    <visual>
      <origin rpy="1.5708 0 0" xyz="0 0 0"/>
      <geometry>
        <sphere radius="0.005"/>
      </geometry>
        <material name="red">
      <color rgba="1 0 0 1"/>
    </material>
    </visual>
  </link>

  <joint name="RL_shoulder_joint" type="fixed">
    <origin xyz="-0.045 0 0" rpy="0 0 0"/>
    <parent link="RL_thigh"/>
    <child link="RL_shoulder"/>
    <axis xyz="0 1 0"/>
  </joint>

  <!-- ========== REAR RIGHT LEG ========== -->
  <link name="RR_hip">
    <inertial>
      <origin xyz="0.0054 -0.00194 -0.000105" rpy="0 0 0"/>
      <mass value="0.678"/>
      <inertia ixx="0.00048" ixy="-3.01E-06" ixz="-1.11E-06" iyy="0.000884" iyz="1.42E-06" izz="0.000596"/>
    </inertial>
    <visual>
      <origin xyz="0 0 0" rpy="3.1415 3.1415 0"/>
      <geometry>
        <mesh filename="package://dae/hip.dae"/>
      </geometry>
      <material name="">
        <color rgba="1 1 1 1"/>
      </material>
    </visual>
    <collision>
      <origin xyz="0 0 0" rpy="3.1415 3.1415 0"/>
      <geometry>
        <mesh filename="package://dae/hip.dae"/>
      </geometry>
    </collision>
  </link>

  <joint name="RR_hip_joint" type="revolute">
    <origin xyz="-0.1934 -0.0465 0" rpy="0 0 0"/>
    <parent link="base_link"/>
    <child link="RR_hip"/>
    <axis xyz="1 0 0"/>
    <limit lower="-1.0472" upper="1.0472" effort="23.7" velocity="30.1"/>
  </joint>

  <link name="RR_thigh">
    <inertial>
      <origin xyz="-0.00374 0.0223 -0.0327" rpy="0 0 0"/>
      <mass value="1.152"/>
      <inertia ixx="0.00584" ixy="-8.72E-05" ixz="-0.000289" iyy="0.0058" iyz="-0.000808" izz="0.00103"/>
    </inertial>
    <visual>
      <origin xyz="0 0 0" rpy="0 0 0"/>
      <geometry>
        <mesh filename="package://dae/thigh_mirror.dae"/>
      </geometry>
      <material name="">
        <color rgba="1 1 1 1"/>
      </material>
    </visual>
    <collision>
    <geometry>
        <mesh filename="package://dae/thigh_mirror.dae"/>
      </geometry>
    </collision>
  </link>

  <joint name="RR_thigh_joint" type="revolute">
    <origin xyz="0 -0.0955 0" rpy="0 0 0"/>
    <parent link="RR_hip"/>
    <child link="RR_thigh"/>
    <axis xyz="0 1 0"/>
    <limit lower="-0.5236" upper="4.5379" effort="23.7" velocity="30.1"/>
  </joint>

  <link name="RR_calf">
    <inertial>
      <origin xyz="0.00548 0.000975 -0.115" rpy="0 0 0"/>
      <mass value="0.154"/>
      <inertia ixx="0.00108" ixy="-3.4E-07" ixz="1.72E-05" iyy="0.0011" iyz="-8.28E-06" izz="3.29E-05"/>
    </inertial>
    <visual>
      <origin xyz="0 0 0" rpy="0 0 0"/>
      <geometry>
        <mesh filename="package://dae/calf_mirror.dae"/>
      </geometry>
      <material name="">
        <color rgba="1 1 1 1"/>
      </material>
    </visual>
    <collision>
      <geometry>
        <mesh filename="package://dae/calf_mirror.dae"/>
      </geometry>
    </collision>
  </link>

  <joint name="RR_calf_joint" type="revolute">
    <origin xyz="0 0 -0.213" rpy="0 0 0"/>
    <parent link="RR_thigh"/>
    <child link="RR_calf"/>
    <axis xyz="0 1 0"/>
    <limit lower="-2.7227" upper="-0.83776" effort="45.43" velocity="15.70"/>
  </joint>

  <link name="RR_foot">
    <inertial>
      <origin xyz="0 0 0" rpy="0 0 0"/>
      <mass value="0.04"/>
      <inertia ixx="9.6e-06" ixy="0" ixz="0" iyy="9.6e-06" iyz="0" izz="9.6e-06"/>
    </inertial>
    <visual>
      <origin xyz="0 0 0" rpy="0 0 0"/>
      <geometry>
        <mesh filename="package://dae/foot.dae"/>
      </geometry>
      <material name="black">
        <color rgba="0 0 0 1"/>
      </material>
    </visual>
    <collision>
      <origin rpy="0 0 0" xyz="-0.002 0 0"/>
      <geometry>
        <sphere radius="0.022"/>
      </geometry>
    </collision>
  </link>

  <joint name="RR_foot_joint" type="fixed" dont_collapse="true">
    <origin xyz="0 0 -0.213" rpy="0 0 0"/>
    <parent link="RR_calf"/>
    <child link="RR_foot"/>
    <axis xyz="0 0 0"/>
  </joint>

  <link name="RR_shoulder">
    <inertial>
      <origin xyz="0 0 0" rpy="0 0 0"/>
      <mass value="0"/>
      <inertia ixx="0" ixy="0" ixz="0" iyy="0" iyz="0" izz="0"/>
    </inertial>
    <visual>
      <origin rpy="1.5708 0 0" xyz="0 0 0"/>
      <geometry>
        <sphere radius="0.005"/>
      </geometry>
        <material name="red">
      <color rgba="1 0 0 1"/>
    </material>
    </visual>
  </link>

  <joint name="RR_shoulder_joint" type="fixed">
    <origin xyz="-0.045 0 0" rpy="0 0 0"/>
    <parent link="RR_thigh"/>
    <child link="RR_shoulder"/>
    <axis xyz="0 1 0"/>
  </joint>

</robot>